Traceback (most recent call last):
  File "/Users/nila1617/example-project/code/task.py", line 19, in <module>
    plt.savefig('/figures/random_walk_' + str(now) + '.png')
  File "/Users/nila1617/example-project/.venv/lib64/python3.6/site-packages/matplotlib/pyplot.py", line 859, in savefig
    res = fig.savefig(*args, **kwargs)
  File "/Users/nila1617/example-project/.venv/lib64/python3.6/site-packages/matplotlib/figure.py", line 2311, in savefig
    self.canvas.print_figure(fname, **kwargs)
  File "/Users/nila1617/example-project/.venv/lib64/python3.6/site-packages/matplotlib/backend_bases.py", line 2217, in print_figure
    **kwargs)
  File "/Users/nila1617/example-project/.venv/lib64/python3.6/site-packages/matplotlib/backend_bases.py", line 1639, in wrapper
    return func(*args, **kwargs)
  File "/Users/nila1617/example-project/.venv/lib64/python3.6/site-packages/matplotlib/backends/backend_agg.py", line 512, in print_png
    dpi=self.figure.dpi, metadata=metadata, pil_kwargs=pil_kwargs)
  File "/Users/nila1617/example-project/.venv/lib64/python3.6/site-packages/matplotlib/image.py", line 1611, in imsave
    image.save(fname, **pil_kwargs)
  File "/Users/nila1617/example-project/.venv/lib64/python3.6/site-packages/PIL/Image.py", line 2237, in save
    fp = builtins.open(filename, "w+b")
FileNotFoundError: [Errno 2] No such file or directory: '/figures/random_walk_2023-11-16 14:16:32.537452.png'
